Workbook

Sheet README
A1: STRAND — Economy Design Spreadsheet
A2: Version 1.1 (FINAL — campaign structure corrected to 20 floors / 4 Zones × 5 per GDD §6)
A3: Owner: Tudor Grigoriu / Empathy Software | Last updated: May 2026
A5: PURPOSE
B6: This workbook is the binding numeric source of truth for STRAND's economy. All gameplay code, balance tuning, and revenue forecasting must read its outputs. When the GDD prose conflicts with this sheet, this sheet wins on numbers.
A8: HOW TO USE
A9: Step 1 | B9: Only ever edit BLUE cells. They live on the Assumptions tab (and a few input columns elsewhere). Everything else is a formula and will recalculate.
A10: Step 2 | B10: If a downstream sheet shows a hash-DIV-0 or hash-REF error, do not patch the symptom — open Validation Checks (sheet 14, batch 5) and find the broken upstream input.
A11: Step 3 | B11: Use the three DAU scenarios on the Revenue tab (batch 4) to test sensitivity. Never change a formula to make the answer prettier.
A12: Step 4 | B12: Bump the version on this README every time you commit a change to Drive.
A14: COLOR CONVENTIONS
A15: Blue text | B15: Hardcoded input. Editable. Lives on Assumptions tab (and clearly-marked input columns elsewhere).
A16: Black text | B16: Formula referencing cells on the SAME sheet. Do not overwrite.
A17: Green text | B17: Formula pulling from ANOTHER sheet in this workbook. Do not overwrite.
A18: Red text | B18: External link to a file outside this workbook. Should not exist in v0.1.
A19: Yellow fill | B19: Key assumption needing director attention before lock.
A21: BATCH STRUCTURE
A22: Batch 1 (this) | B22: Foundation: README, Assumptions, Player Stats Curve, XP & Level Curve, Drop Rates.
A23: Batch 2 | B23: World & Pacing: Enemy Stats, Currencies, Run Pacing.
A24: Batch 3 | B24: Economy surfaces: Mutation Costs, IAP Catalog.
A25: Batch 4 | B25: Business model: DAU & Revenue Model, Cost Projection.
A26: Batch 5 | B26: Validation: Pass Sensitivity, Validation Checks.
A28: DEPENDENCIES
B29: Assumptions ← (foundation)
B30: Player Stats Curve, XP & Level Curve, Drop Rates ← Assumptions
B31: Enemy Stats ← Player Stats; Currencies ← Drop Rates; Run Pacing ← Player + Enemy
B32: Mutation Costs, IAP Catalog ← Currencies
B33: DAU & Revenue ← IAP Catalog; Cost Projection ← DAU
B34: Pass Sensitivity ← DAU + IAP; Validation Checks ← everything
A36: OPEN QUESTIONS (BATCH 1)
A37: Q1 | B37: Floor count: 20 floors / 4 Zones × 5 floors, bosses at 5/10/15/20. Locked per GDD §6 & Concept One-Pager. (v1.0 inherited a superseded 30-floor draft; corrected in v1.1.)
A38: Q2 | B38: Player HP scaling shape: geometric ratio 1.08 — confirm against playtest in prototype.
A39: Q3 | B39: Level cap: 60. Higher than max floor so post-content grind has headroom.
A40: Q4 | B40: VEIN drop rate per common kill: 8 — placeholder. Will be revisited in batch 2 once Currencies tab exists.
A42: VERSION HISTORY
A43: v0.1 | B43: Batch 1 — May 2026 — Foundation layer (5 sheets). Pending batches 2–5.
A44: v0.2 | B44: Batch 2 — May 2026 — Added Enemy Stats, Currencies, Run Pacing. Added 2 new assumptions: shard_per_vein_conversion, vein_per_floor_clear_bonus.
A45: v0.2.1 | B45: Cleanup: extracted combat timing (6s/turn, 30s nav, 15s reward) to Assumptions. Replaced hardcoded boss flags (0*/1*) in Currencies VEIN/SIG with MOD-based formulas that react to boss_every_n_floors. Unified Run Pacing combat formula across boss and non-boss floors. Re-colored cross-sheet refs green where they had been black. Note: Enemy Stats row layout and Run Pacing column F still encode boss_every_n_floors=6 at workbook generation time; changing that assumption requires regenerating the workbook from script, not just a recalc.
A46: v0.3 | B46: Batch 3 — May 2026 — Added Mutation Costs (cost matrix by rarity × level, with balance check against SIG-earned-per-run) and IAP Catalog (6 SKUs with USD prices, currency grants, time-saved per dollar, and value ratings). Added 22 new assumptions for mutation costs (7) and IAP pricing/benchmarks (15).
A47: v0.3.1 | B47: Shard IAP rebalance: dropped iap_shard_small_amount (100→6), iap_shard_large_amount (600→40), and iap_pass_shard_grant (300→20). Calibrated against Shard earn rate of 0.08/min so Small Shard pack saves ~74 min (Fair value, entry tier), Large saves ~491 min (Strong, whale tier), and the Pass stays the best deal in the catalog at ~736 min saved for $9.99. VEIN packs unchanged — they were already in the right range (30-46 min per dollar).
...

Sheet Assumptions
A1: ASSUMPTIONS — Every Input Variable
A2: Edit ONLY the blue cells. Yellow-filled rows require director sign-off before lock.
A4: # | B4: Variable | C4: Value | D4: Unit | E4: Notes / Source
A5: GAME STRUCTURE
A6: 1 | B6: max_floor | C6: 20 | D6: floor | E6: 20 floors total. Per GDD §6 / Concept One-Pager: 20 floors across 4 Zones of 5.
A7: 2 | B7: level_cap | C7: 60 | D7: level | E7: Higher than max floor — gives post-content runway.
A8: 3 | B8: zones_count | C8: 4 | D8: zones | E8: Each zone is 5 floors (4 × 5 = 20). Shallows / Mycosphere / Lithic / Convergence.
A9: 4 | B9: floors_per_zone | C9: 5 | D9: floors | E9: Check: floors_per_zone × zones_count = max_floor (5 × 4 = 20).
A10: 5 | B10: enemy_tiers | C10: 3 | D10: tiers | E10: Common / Elite / Boss per zone.
A11: PLAYER PROGRESSION
A12: 6 | B12: hp_base | C12: 100 | D12: HP | E12: HP at level 1 / floor 1.
A13: 7 | B13: hp_growth_per_floor | C13: 0.08 | D13: ratio | E13: Geometric scaling. 1.08^19 ≈ 4.3x HP at floor 20.
A14: 8 | B14: ap_base | C14: 3 | D14: AP | E14: Action points per turn at start.
A15: 9 | B15: ap_floor_bonus_every | C15: 10 | D15: floors | E15: +1 AP every N floors. Currently every 10.
A16: 10 | B16: damage_base | C16: 12 | D16: dmg | E16: Player base attack damage at floor 1.
A17: 11 | B17: damage_growth_per_floor | C17: 0.1 | D17: ratio | E17: Geometric. 1.10^19 ≈ 6.1x player damage at floor 20.
A18: XP & LEVELING
A19: 12 | B19: xp_base | C19: 100 | D19: XP | E19: XP required from level 1 to level 2.
A20: 13 | B20: xp_growth_per_level | C20: 0.15 | D20: ratio | E20: Each level needs 15% more XP than the last.
A21: 14 | B21: xp_per_floor_clear | C21: 25 | D21: XP | E21: Base XP awarded for clearing one floor (multiplied by floor #).
A22: 15 | B22: xp_per_elite_kill | C22: 15 | D22: XP | E22: Awarded per elite enemy killed.
A23: 16 | B23: xp_per_boss_kill | C23: 80 | D23: XP | E23: Awarded per zone boss killed.
A24: ENEMY SCALING (used in batch 2)
A25: 17 | B25: enemy_hp_base | C25: 40 | D25: HP | E25: Common enemy HP at floor 1.
A26: 18 | B26: enemy_hp_growth | C26: 0.09 | D26: ratio | E26: Geometric per floor. Should outpace player damage growth (0.07) so combat tightens.
A27: 19 | B27: elite_hp_multiplier | C27: 3 | D27: x | E27: Elite = 3.0 × common HP at same floor.
A28: 20 | B28: boss_hp_multiplier | C28: 8 | D28: x | E28: Boss = 8.0 × common HP at same floor.
A29: 21 | B29: enemy_dmg_base | C29: 6 | D29: dmg | E29: Common enemy attack damage at floor 1.
A30: 22 | B30: enemy_dmg_growth | C30: 0.08 | D30: ratio | E30: Geometric per floor.
A31: 23 | B31: elite_dmg_multiplier | C31: 1.6 | D31: x
A32: 24 | B32: boss_dmg_multiplier | C32: 2.5 | D32: x
A33: DROP RATES — base probabilities (per kill)
A34: 25 | B34: drop_common_vein_pct | C34: 1 | D34: % | E34: Every common kill drops VEIN.
A35: 26 | B35: drop_common_sig_pct | C35: 0.2 | D35: % | E35: 20% chance a common kill drops SIG.
A36: 27 | B36: drop_common_mod_pct | C36: 0.05 | D36: % | E36: 5% chance a common kill drops a generic Mod token.
A37: 28 | B37: drop_elite_sig_pct | C37: 0.65 | D37: % | E37: 65% chance an elite drops SIG.
A38: 29 | B38: drop_elite_mod_pct | C38: 0.3 | D38: % | E38: 30% chance an elite drops a Mod token.
A39: 30 | B39: drop_elite_rare_pct | C39: 0.1 | D39: % | E39: 10% chance an elite drops a Rare mutation core.
A40: 31 | B40: drop_boss_sig | C40: 1 | D40: % | E40: Bosses guarantee SIG drop.
A41: 32 | B41: drop_boss_rare_pct | C41: 0.6 | D41: % | E41: 60% chance boss drops Rare core.
...

Sheet Player Stats Curve
A1: PLAYER STATS CURVE
A2: Driven entirely by Assumptions. All formulas in black are same-sheet; green pulls cross-sheet.
A4: DRIVER INPUTS (mirrored from Assumptions — green text)
A5: Driver | B5: Value
A6: hp_base | B6: =Assumptions!$C$12
A7: hp_growth_per_floor | B7: =Assumptions!$C$13
A8: ap_base | B8: =Assumptions!$C$14
A9: ap_floor_bonus_every | B9: =Assumptions!$C$15
A10: damage_base | B10: =Assumptions!$C$16
A11: damage_growth_per_floor | B11: =Assumptions!$C$17
A12: max_floor | B12: =Assumptions!$C$6
A14: PER-FLOOR CURVE
A15: Floor | B15: Player HP | C15: Player Damage | D15: Player AP | E15: HP vs Floor 1 | F15: Dmg vs Floor 1 | G15: Notes
A16: 1 | B16: =$B$6*(1+$B$7)^(A16-1) | C16: =$B$10*(1+$B$11)^(A16-1) | D16: =$B$8+INT((A16-1)/$B$9) | E16: =B16/$B$16 | F16: =C16/$C$16
A17: 2 | B17: =$B$6*(1+$B$7)^(A17-1) | C17: =$B$10*(1+$B$11)^(A17-1) | D17: =$B$8+INT((A17-1)/$B$9) | E17: =B17/$B$16 | F17: =C17/$C$16
A18: 3 | B18: =$B$6*(1+$B$7)^(A18-1) | C18: =$B$10*(1+$B$11)^(A18-1) | D18: =$B$8+INT((A18-1)/$B$9) | E18: =B18/$B$16 | F18: =C18/$C$16
A19: 4 | B19: =$B$6*(1+$B$7)^(A19-1) | C19: =$B$10*(1+$B$11)^(A19-1) | D19: =$B$8+INT((A19-1)/$B$9) | E19: =B19/$B$16 | F19: =C19/$C$16
A20: 5 | B20: =$B$6*(1+$B$7)^(A20-1) | C20: =$B$10*(1+$B$11)^(A20-1) | D20: =$B$8+INT((A20-1)/$B$9) | E20: =B20/$B$16 | F20: =C20/$C$16 | G20: Zone 1 boss floor
A21: 6 | B21: =$B$6*(1+$B$7)^(A21-1) | C21: =$B$10*(1+$B$11)^(A21-1) | D21: =$B$8+INT((A21-1)/$B$9) | E21: =B21/$B$16 | F21: =C21/$C$16
A22: 7 | B22: =$B$6*(1+$B$7)^(A22-1) | C22: =$B$10*(1+$B$11)^(A22-1) | D22: =$B$8+INT((A22-1)/$B$9) | E22: =B22/$B$16 | F22: =C22/$C$16
A23: 8 | B23: =$B$6*(1+$B$7)^(A23-1) | C23: =$B$10*(1+$B$11)^(A23-1) | D23: =$B$8+INT((A23-1)/$B$9) | E23: =B23/$B$16 | F23: =C23/$C$16
A24: 9 | B24: =$B$6*(1+$B$7)^(A24-1) | C24: =$B$10*(1+$B$11)^(A24-1) | D24: =$B$8+INT((A24-1)/$B$9) | E24: =B24/$B$16 | F24: =C24/$C$16
A25: 10 | B25: =$B$6*(1+$B$7)^(A25-1) | C25: =$B$10*(1+$B$11)^(A25-1) | D25: =$B$8+INT((A25-1)/$B$9) | E25: =B25/$B$16 | F25: =C25/$C$16 | G25: Zone 2 boss floor
A26: 11 | B26: =$B$6*(1+$B$7)^(A26-1) | C26: =$B$10*(1+$B$11)^(A26-1) | D26: =$B$8+INT((A26-1)/$B$9) | E26: =B26/$B$16 | F26: =C26/$C$16
A27: 12 | B27: =$B$6*(1+$B$7)^(A27-1) | C27: =$B$10*(1+$B$11)^(A27-1) | D27: =$B$8+INT((A27-1)/$B$9) | E27: =B27/$B$16 | F27: =C27/$C$16
A28: 13 | B28: =$B$6*(1+$B$7)^(A28-1) | C28: =$B$10*(1+$B$11)^(A28-1) | D28: =$B$8+INT((A28-1)/$B$9) | E28: =B28/$B$16 | F28: =C28/$C$16
A29: 14 | B29: =$B$6*(1+$B$7)^(A29-1) | C29: =$B$10*(1+$B$11)^(A29-1) | D29: =$B$8+INT((A29-1)/$B$9) | E29: =B29/$B$16 | F29: =C29/$C$16
A30: 15 | B30: =$B$6*(1+$B$7)^(A30-1) | C30: =$B$10*(1+$B$11)^(A30-1) | D30: =$B$8+INT((A30-1)/$B$9) | E30: =B30/$B$16 | F30: =C30/$C$16 | G30: Zone 3 boss floor
A31: 16 | B31: =$B$6*(1+$B$7)^(A31-1) | C31: =$B$10*(1+$B$11)^(A31-1) | D31: =$B$8+INT((A31-1)/$B$9) | E31: =B31/$B$16 | F31: =C31/$C$16
A32: 17 | B32: =$B$6*(1+$B$7)^(A32-1) | C32: =$B$10*(1+$B$11)^(A32-1) | D32: =$B$8+INT((A32-1)/$B$9) | E32: =B32/$B$16 | F32: =C32/$C$16
A33: 18 | B33: =$B$6*(1+$B$7)^(A33-1) | C33: =$B$10*(1+$B$11)^(A33-1) | D33: =$B$8+INT((A33-1)/$B$9) | E33: =B33/$B$16 | F33: =C33/$C$16
A34: 19 | B34: =$B$6*(1+$B$7)^(A34-1) | C34: =$B$10*(1+$B$11)^(A34-1) | D34: =$B$8+INT((A34-1)/$B$9) | E34: =B34/$B$16 | F34: =C34/$C$16
A35: 20 | B35: =$B$6*(1+$B$7)^(A35-1) | C35: =$B$10*(1+$B$11)^(A35-1) | D35: =$B$8+INT((A35-1)/$B$9) | E35: =B35/$B$16 | F35: =C35/$C$16 | G35: Zone 4 boss floor

Sheet XP & Level Curve
A1: XP & LEVEL CURVE
A2: XP required per level + cumulative + unlocks. Drives the leveling pace in Run Pacing (batch 2).
A4: DRIVER INPUTS
A5: Driver | B5: Value
A6: xp_base | B6: =Assumptions!$C$19
A7: xp_growth_per_level | B7: =Assumptions!$C$20
A8: level_cap | B8: =Assumptions!$C$7
A10: PER-LEVEL TABLE
A11: Level | B11: XP to next | C11: Cumulative XP | D11: XP vs Level 1 | E11: Unlocks at this level | F11: Notes
A12: 1 | B12: =ROUND($B$6*(1+$B$7)^(A12-1),0) | C12: =0 | D12: =B12/$B$12 | E12: Tutorial / Floor 0 access
A13: 2 | B13: =ROUND($B$6*(1+$B$7)^(A13-1),0) | C13: =C12+B12 | D13: =B13/$B$12 | E13: First mutation slot
A14: 3 | B14: =ROUND($B$6*(1+$B$7)^(A14-1),0) | C14: =C13+B13 | D14: =B14/$B$12 | E14: Codex unlock
A15: 4 | B15: =ROUND($B$6*(1+$B$7)^(A15-1),0) | C15: =C14+B14 | D15: =B15/$B$12
A16: 5 | B16: =ROUND($B$6*(1+$B$7)^(A16-1),0) | C16: =C15+B15 | D16: =B16/$B$12 | E16: Second mutation slot
A17: 6 | B17: =ROUND($B$6*(1+$B$7)^(A17-1),0) | C17: =C16+B16 | D17: =B17/$B$12
A18: 7 | B18: =ROUND($B$6*(1+$B$7)^(A18-1),0) | C18: =C17+B17 | D18: =B18/$B$12
A19: 8 | B19: =ROUND($B$6*(1+$B$7)^(A19-1),0) | C19: =C18+B18 | D19: =B19/$B$12 | E19: Crafting bench (Mod combine)
A20: 9 | B20: =ROUND($B$6*(1+$B$7)^(A20-1),0) | C20: =C19+B19 | D20: =B20/$B$12
A21: 10 | B21: =ROUND($B$6*(1+$B$7)^(A21-1),0) | C21: =C20+B20 | D21: =B21/$B$12 | E21: Third mutation slot
A22: 11 | B22: =ROUND($B$6*(1+$B$7)^(A22-1),0) | C22: =C21+B21 | D22: =B22/$B$12
A23: 12 | B23: =ROUND($B$6*(1+$B$7)^(A23-1),0) | C23: =C22+B22 | D23: =B23/$B$12 | E23: Daily Strand challenge unlocked
A24: 13 | B24: =ROUND($B$6*(1+$B$7)^(A24-1),0) | C24: =C23+B23 | D24: =B24/$B$12
A25: 14 | B25: =ROUND($B$6*(1+$B$7)^(A25-1),0) | C25: =C24+B24 | D25: =B25/$B$12
A26: 15 | B26: =ROUND($B$6*(1+$B$7)^(A26-1),0) | C26: =C25+B25 | D26: =B26/$B$12 | E26: Loadout presets (3 slots)
A27: 16 | B27: =ROUND($B$6*(1+$B$7)^(A27-1),0) | C27: =C26+B26 | D27: =B27/$B$12
A28: 17 | B28: =ROUND($B$6*(1+$B$7)^(A28-1),0) | C28: =C27+B27 | D28: =B28/$B$12
A29: 18 | B29: =ROUND($B$6*(1+$B$7)^(A29-1),0) | C29: =C28+B28 | D29: =B29/$B$12 | E29: Weekly Strand event unlocked
A30: 19 | B30: =ROUND($B$6*(1+$B$7)^(A30-1),0) | C30: =C29+B29 | D30: =B30/$B$12
A31: 20 | B31: =ROUND($B$6*(1+$B$7)^(A31-1),0) | C31: =C30+B30 | D31: =B31/$B$12 | E31: Fourth mutation slot
A32: 21 | B32: =ROUND($B$6*(1+$B$7)^(A32-1),0) | C32: =C31+B31 | D32: =B32/$B$12
A33: 22 | B33: =ROUND($B$6*(1+$B$7)^(A33-1),0) | C33: =C32+B32 | D33: =B33/$B$12
A34: 23 | B34: =ROUND($B$6*(1+$B$7)^(A34-1),0) | C34: =C33+B33 | D34: =B34/$B$12
A35: 24 | B35: =ROUND($B$6*(1+$B$7)^(A35-1),0) | C35: =C34+B34 | D35: =B35/$B$12
A36: 25 | B36: =ROUND($B$6*(1+$B$7)^(A36-1),0) | C36: =C35+B35 | D36: =B36/$B$12 | E36: Prestige Tier I unlocks
A37: 26 | B37: =ROUND($B$6*(1+$B$7)^(A37-1),0) | C37: =C36+B36 | D37: =B37/$B$12
A38: 27 | B38: =ROUND($B$6*(1+$B$7)^(A38-1),0) | C38: =C37+B37 | D38: =B38/$B$12
A39: 28 | B39: =ROUND($B$6*(1+$B$7)^(A39-1),0) | C39: =C38+B38 | D39: =B39/$B$12
A40: 29 | B40: =ROUND($B$6*(1+$B$7)^(A40-1),0) | C40: =C39+B39 | D40: =B40/$B$12
A41: 30 | B41: =ROUND($B$6*(1+$B$7)^(A41-1),0) | C41: =C40+B40 | D41: =B41/$B$12 | E41: Endgame Floor 30 boss eligible
A42: 31 | B42: =ROUND($B$6*(1+$B$7)^(A42-1),0) | C42: =C41+B41 | D42: =B42/$B$12
...

Sheet Drop Rates
A1: DROP RATES
A2: Per-kill drop probabilities and expected per-floor yields. Drives the Currencies tab in batch 2.
A4: GLOBAL DROP PROBABILITIES (per kill, from Assumptions)
A5: Tier | B5: Drop | C5: Probability | K5: LOCAL DRIVERS
A6: Common | B6: VEIN | C6: =Assumptions!$C$34 | K6: commons_per_floor | L6: =Assumptions!$C$51
A7: Common | B7: SIG | C7: =Assumptions!$C$35 | K7: elites_per_floor | L7: =Assumptions!$C$52
A8: Common | B8: Mod | C8: =Assumptions!$C$36 | K8: boss_every_n_floors | L8: =Assumptions!$C$53
A9: Elite | B9: SIG | C9: =Assumptions!$C$37 | K9: floors_per_zone | L9: =Assumptions!$C$9
A10: Elite | B10: Mod | C10: =Assumptions!$C$38
A11: Elite | B11: Rare core | C11: =Assumptions!$C$39
A12: Boss | B12: SIG (guaranteed) | C12: =Assumptions!$C$40
A13: Boss | B13: Rare core | C13: =Assumptions!$C$41
A14: Boss | B14: Epic core | C14: =Assumptions!$C$42
A17: EXPECTED PER-FLOOR YIELD (E[drops] = kills × probability)
A18: Floor | B18: Zone | C18: Commons | D18: Elites | E18: E[VEIN drops] | F18: E[SIG drops] | G18: E[Mod drops] | H18: E[Rare cores] | I18: E[Epic cores] | J18: Is boss floor? | L18: Notes
A19: 1 | B19: =CEILING(A19/$L$9,1) | C19: =IF(MOD(A19,$L$8)=0,$L$6*0.5,$L$6) | D19: =IF(MOD(A19,$L$8)=0,0,$L$7) | E19: =C19*$C$6+D19+IF(MOD(A19,$L$8)=0,1,0) | F19: =C19*$C$7+D19*$C$9+IF(MOD(A19,$L$8)=0,1,0)*$C$12 | G19: =C19*$C$8+D19*$C$10 | H19: =D19*$C$11+IF(MOD(A19,$L$8)=0,1,0)*$C$13 | I19: =IF(MOD(A19,$L$8)=0,1,0)*$C$14 | J19: =IF(MOD(A19,$L$8)=0,"Yes","") | L19: Tutorial floor — drops still apply for balance-data parity.
A20: 2 | B20: =CEILING(A20/$L$9,1) | C20: =IF(MOD(A20,$L$8)=0,$L$6*0.5,$L$6) | D20: =IF(MOD(A20,$L$8)=0,0,$L$7) | E20: =C20*$C$6+D20+IF(MOD(A20,$L$8)=0,1,0) | F20: =C20*$C$7+D20*$C$9+IF(MOD(A20,$L$8)=0,1,0)*$C$12 | G20: =C20*$C$8+D20*$C$10 | H20: =D20*$C$11+IF(MOD(A20,$L$8)=0,1,0)*$C$13 | I20: =IF(MOD(A20,$L$8)=0,1,0)*$C$14 | J20: =IF(MOD(A20,$L$8)=0,"Yes","")
A21: 3 | B21: =CEILING(A21/$L$9,1) | C21: =IF(MOD(A21,$L$8)=0,$L$6*0.5,$L$6) | D21: =IF(MOD(A21,$L$8)=0,0,$L$7) | E21: =C21*$C$6+D21+IF(MOD(A21,$L$8)=0,1,0) | F21: =C21*$C$7+D21*$C$9+IF(MOD(A21,$L$8)=0,1,0)*$C$12 | G21: =C21*$C$8+D21*$C$10 | H21: =D21*$C$11+IF(MOD(A21,$L$8)=0,1,0)*$C$13 | I21: =IF(MOD(A21,$L$8)=0,1,0)*$C$14 | J21: =IF(MOD(A21,$L$8)=0,"Yes","")
A22: 4 | B22: =CEILING(A22/$L$9,1) | C22: =IF(MOD(A22,$L$8)=0,$L$6*0.5,$L$6) | D22: =IF(MOD(A22,$L$8)=0,0,$L$7) | E22: =C22*$C$6+D22+IF(MOD(A22,$L$8)=0,1,0) | F22: =C22*$C$7+D22*$C$9+IF(MOD(A22,$L$8)=0,1,0)*$C$12 | G22: =C22*$C$8+D22*$C$10 | H22: =D22*$C$11+IF(MOD(A22,$L$8)=0,1,0)*$C$13 | I22: =IF(MOD(A22,$L$8)=0,1,0)*$C$14 | J22: =IF(MOD(A22,$L$8)=0,"Yes","")
A23: 5 | B23: =CEILING(A23/$L$9,1) | C23: =IF(MOD(A23,$L$8)=0,$L$6*0.5,$L$6) | D23: =IF(MOD(A23,$L$8)=0,0,$L$7) | E23: =C23*$C$6+D23+IF(MOD(A23,$L$8)=0,1,0) | F23: =C23*$C$7+D23*$C$9+IF(MOD(A23,$L$8)=0,1,0)*$C$12 | G23: =C23*$C$8+D23*$C$10 | H23: =D23*$C$11+IF(MOD(A23,$L$8)=0,1,0)*$C$13 | I23: =IF(MOD(A23,$L$8)=0,1,0)*$C$14 | J23: =IF(MOD(A23,$L$8)=0,"Yes","") | L23: Zone 1 boss
A24: 6 | B24: =CEILING(A24/$L$9,1) | C24: =IF(MOD(A24,$L$8)=0,$L$6*0.5,$L$6) | D24: =IF(MOD(A24,$L$8)=0,0,$L$7) | E24: =C24*$C$6+D24+IF(MOD(A24,$L$8)=0,1,0) | F24: =C24*$C$7+D24*$C$9+IF(MOD(A24,$L$8)=0,1,0)*$C$12 | G24: =C24*$C$8+D24*$C$10 | H24: =D24*$C$11+IF(MOD(A24,$L$8)=0,1,0)*$C$13 | I24: =IF(MOD(A24,$L$8)=0,1,0)*$C$14 | J24: =IF(MOD(A24,$L$8)=0,"Yes","")
A25: 7 | B25: =CEILING(A25/$L$9,1) | C25: =IF(MOD(A25,$L$8)=0,$L$6*0.5,$L$6) | D25: =IF(MOD(A25,$L$8)=0,0,$L$7) | E25: =C25*$C$6+D25+IF(MOD(A25,$L$8)=0,1,0) | F25: =C25*$C$7+D25*$C$9+IF(MOD(A25,$L$8)=0,1,0)*$C$12 | G25: =C25*$C$8+D25*$C$10 | H25: =D25*$C$11+IF(MOD(A25,$L$8)=0,1,0)*$C$13 | I25: =IF(MOD(A25,$L$8)=0,1,0)*$C$14 | J25: =IF(MOD(A25,$L$8)=0,"Yes","")
A26: 8 | B26: =CEILING(A26/$L$9,1) | C26: =IF(MOD(A26,$L$8)=0,$L$6*0.5,$L$6) | D26: =IF(MOD(A26,$L$8)=0,0,$L$7) | E26: =C26*$C$6+D26+IF(MOD(A26,$L$8)=0,1,0) | F26: =C26*$C$7+D26*$C$9+IF(MOD(A26,$L$8)=0,1,0)*$C$12 | G26: =C26*$C$8+D26*$C$10 | H26: =D26*$C$11+IF(MOD(A26,$L$8)=0,1,0)*$C$13 | I26: =IF(MOD(A26,$L$8)=0,1,0)*$C$14 | J26: =IF(MOD(A26,$L$8)=0,"Yes","")
A27: 9 | B27: =CEILING(A27/$L$9,1) | C27: =IF(MOD(A27,$L$8)=0,$L$6*0.5,$L$6) | D27: =IF(MOD(A27,$L$8)=0,0,$L$7) | E27: =C27*$C$6+D27+IF(MOD(A27,$L$8)=0,1,0) | F27: =C27*$C$7+D27*$C$9+IF(MOD(A27,$L$8)=0,1,0)*$C$12 | G27: =C27*$C$8+D27*$C$10 | H27: =D27*$C$11+IF(MOD(A27,$L$8)=0,1,0)*$C$13 | I27: =IF(MOD(A27,$L$8)=0,1,0)*$C$14 | J27: =IF(MOD(A27,$L$8)=0,"Yes","")
A28: 10 | B28: =CEILING(A28/$L$9,1) | C28: =IF(MOD(A28,$L$8)=0,$L$6*0.5,$L$6) | D28: =IF(MOD(A28,$L$8)=0,0,$L$7) | E28: =C28*$C$6+D28+IF(MOD(A28,$L$8)=0,1,0) | F28: =C28*$C$7+D28*$C$9+IF(MOD(A28,$L$8)=0,1,0)*$C$12 | G28: =C28*$C$8+D28*$C$10 | H28: =D28*$C$11+IF(MOD(A28,$L$8)=0,1,0)*$C$13 | I28: =IF(MOD(A28,$L$8)=0,1,0)*$C$14 | J28: =IF(MOD(A28,$L$8)=0,"Yes","") | L28: Zone 2 boss
A29: 11 | B29: =CEILING(A29/$L$9,1) | C29: =IF(MOD(A29,$L$8)=0,$L$6*0.5,$L$6) | D29: =IF(MOD(A29,$L$8)=0,0,$L$7) | E29: =C29*$C$6+D29+IF(MOD(A29,$L$8)=0,1,0) | F29: =C29*$C$7+D29*$C$9+IF(MOD(A29,$L$8)=0,1,0)*$C$12 | G29: =C29*$C$8+D29*$C$10 | H29: =D29*$C$11+IF(MOD(A29,$L$8)=0,1,0)*$C$13 | I29: =IF(MOD(A29,$L$8)=0,1,0)*$C$14 | J29: =IF(MOD(A29,$L$8)=0,"Yes","")
A30: 12 | B30: =CEILING(A30/$L$9,1) | C30: =IF(MOD(A30,$L$8)=0,$L$6*0.5,$L$6) | D30: =IF(MOD(A30,$L$8)=0,0,$L$7) | E30: =C30*$C$6+D30+IF(MOD(A30,$L$8)=0,1,0) | F30: =C30*$C$7+D30*$C$9+IF(MOD(A30,$L$8)=0,1,0)*$C$12 | G30: =C30*$C$8+D30*$C$10 | H30: =D30*$C$11+IF(MOD(A30,$L$8)=0,1,0)*$C$13 | I30: =IF(MOD(A30,$L$8)=0,1,0)*$C$14 | J30: =IF(MOD(A30,$L$8)=0,"Yes","")
A31: 13 | B31: =CEILING(A31/$L$9,1) | C31: =IF(MOD(A31,$L$8)=0,$L$6*0.5,$L$6) | D31: =IF(MOD(A31,$L$8)=0,0,$L$7) | E31: =C31*$C$6+D31+IF(MOD(A31,$L$8)=0,1,0) | F31: =C31*$C$7+D31*$C$9+IF(MOD(A31,$L$8)=0,1,0)*$C$12 | G31: =C31*$C$8+D31*$C$10 | H31: =D31*$C$11+IF(MOD(A31,$L$8)=0,1,0)*$C$13 | I31: =IF(MOD(A31,$L$8)=0,1,0)*$C$14 | J31: =IF(MOD(A31,$L$8)=0,"Yes","")
A32: 14 | B32: =CEILING(A32/$L$9,1) | C32: =IF(MOD(A32,$L$8)=0,$L$6*0.5,$L$6) | D32: =IF(MOD(A32,$L$8)=0,0,$L$7) | E32: =C32*$C$6+D32+IF(MOD(A32,$L$8)=0,1,0) | F32: =C32*$C$7+D32*$C$9+IF(MOD(A32,$L$8)=0,1,0)*$C$12 | G32: =C32*$C$8+D32*$C$10 | H32: =D32*$C$11+IF(MOD(A32,$L$8)=0,1,0)*$C$13 | I32: =IF(MOD(A32,$L$8)=0,1,0)*$C$14 | J32: =IF(MOD(A32,$L$8)=0,"Yes","")
A33: 15 | B33: =CEILING(A33/$L$9,1) | C33: =IF(MOD(A33,$L$8)=0,$L$6*0.5,$L$6) | D33: =IF(MOD(A33,$L$8)=0,0,$L$7) | E33: =C33*$C$6+D33+IF(MOD(A33,$L$8)=0,1,0) | F33: =C33*$C$7+D33*$C$9+IF(MOD(A33,$L$8)=0,1,0)*$C$12 | G33: =C33*$C$8+D33*$C$10 | H33: =D33*$C$11+IF(MOD(A33,$L$8)=0,1,0)*$C$13 | I33: =IF(MOD(A33,$L$8)=0,1,0)*$C$14 | J33: =IF(MOD(A33,$L$8)=0,"Yes","") | L33: Zone 3 boss
A34: 16 | B34: =CEILING(A34/$L$9,1) | C34: =IF(MOD(A34,$L$8)=0,$L$6*0.5,$L$6) | D34: =IF(MOD(A34,$L$8)=0,0,$L$7) | E34: =C34*$C$6+D34+IF(MOD(A34,$L$8)=0,1,0) | F34: =C34*$C$7+D34*$C$9+IF(MOD(A34,$L$8)=0,1,0)*$C$12 | G34: =C34*$C$8+D34*$C$10 | H34: =D34*$C$11+IF(MOD(A34,$L$8)=0,1,0)*$C$13 | I34: =IF(MOD(A34,$L$8)=0,1,0)*$C$14 | J34: =IF(MOD(A34,$L$8)=0,"Yes","")
A35: 17 | B35: =CEILING(A35/$L$9,1) | C35: =IF(MOD(A35,$L$8)=0,$L$6*0.5,$L$6) | D35: =IF(MOD(A35,$L$8)=0,0,$L$7) | E35: =C35*$C$6+D35+IF(MOD(A35,$L$8)=0,1,0) | F35: =C35*$C$7+D35*$C$9+IF(MOD(A35,$L$8)=0,1,0)*$C$12 | G35: =C35*$C$8+D35*$C$10 | H35: =D35*$C$11+IF(MOD(A35,$L$8)=0,1,0)*$C$13 | I35: =IF(MOD(A35,$L$8)=0,1,0)*$C$14 | J35: =IF(MOD(A35,$L$8)=0,"Yes","")
A36: 18 | B36: =CEILING(A36/$L$9,1) | C36: =IF(MOD(A36,$L$8)=0,$L$6*0.5,$L$6) | D36: =IF(MOD(A36,$L$8)=0,0,$L$7) | E36: =C36*$C$6+D36+IF(MOD(A36,$L$8)=0,1,0) | F36: =C36*$C$7+D36*$C$9+IF(MOD(A36,$L$8)=0,1,0)*$C$12 | G36: =C36*$C$8+D36*$C$10 | H36: =D36*$C$11+IF(MOD(A36,$L$8)=0,1,0)*$C$13 | I36: =IF(MOD(A36,$L$8)=0,1,0)*$C$14 | J36: =IF(MOD(A36,$L$8)=0,"Yes","")
A37: 19 | B37: =CEILING(A37/$L$9,1) | C37: =IF(MOD(A37,$L$8)=0,$L$6*0.5,$L$6) | D37: =IF(MOD(A37,$L$8)=0,0,$L$7) | E37: =C37*$C$6+D37+IF(MOD(A37,$L$8)=0,1,0) | F37: =C37*$C$7+D37*$C$9+IF(MOD(A37,$L$8)=0,1,0)*$C$12 | G37: =C37*$C$8+D37*$C$10 | H37: =D37*$C$11+IF(MOD(A37,$L$8)=0,1,0)*$C$13 | I37: =IF(MOD(A37,$L$8)=0,1,0)*$C$14 | J37: =IF(MOD(A37,$L$8)=0,"Yes","")
A38: 20 | B38: =CEILING(A38/$L$9,1) | C38: =IF(MOD(A38,$L$8)=0,$L$6*0.5,$L$6) | D38: =IF(MOD(A38,$L$8)=0,0,$L$7) | E38: =C38*$C$6+D38+IF(MOD(A38,$L$8)=0,1,0) | F38: =C38*$C$7+D38*$C$9+IF(MOD(A38,$L$8)=0,1,0)*$C$12 | G38: =C38*$C$8+D38*$C$10 | H38: =D38*$C$11+IF(MOD(A38,$L$8)=0,1,0)*$C$13 | I38: =IF(MOD(A38,$L$8)=0,1,0)*$C$14 | J38: =IF(MOD(A38,$L$8)=0,"Yes","") | L38: Zone 4 boss
A49: CAMPAIGN TOTALS (sum of all floors)
A50: TOTAL | C50: =SUM(C19:C38) | D50: =SUM(D19:D38) | E50: =SUM(E19:E38) | F50: =SUM(F19:F38) | G50: =SUM(G19:G38) | H50: =SUM(H19:H38) | I50: =SUM(I19:I38)

Sheet Enemy Stats
A1: ENEMY STATS
A2: Per-floor enemy HP, Damage, and AP for Common / Elite / Boss tiers. Balance Ratio = enemy HP ÷ player damage = expected turns-to-kill.
A4: DRIVER INPUTS (mirrored from Assumptions — green text)
A5: Driver | B5: Value
A6: enemy_hp_base | B6: =Assumptions!$C$25
A7: enemy_hp_growth | B7: =Assumptions!$C$26
A8: elite_hp_multiplier | B8: =Assumptions!$C$27
A9: boss_hp_multiplier | B9: =Assumptions!$C$28
A10: enemy_dmg_base | B10: =Assumptions!$C$29
A11: enemy_dmg_growth | B11: =Assumptions!$C$30
A12: elite_dmg_multiplier | B12: =Assumptions!$C$31
A13: boss_dmg_multiplier | B13: =Assumptions!$C$32
A14: boss_every_n_floors | B14: =Assumptions!$C$53
A15: floors_per_zone | B15: =Assumptions!$C$9
A17: PER-FLOOR ENEMY STATS
A18: Floor | B18: Zone | C18: Tier | D18: HP | E18: Damage | F18: Player Dmg | G18: Turns-to-Kill | H18: vs Floor 1 HP | I18: Boss? | K18: Notes
A19: 1 | B19: =CEILING(A19/$B$15,1) | C19: Common | D19: =$B$6*(1+$B$7)^(A19-1) | E19: =$B$10*(1+$B$11)^(A19-1) | F19: ='Player Stats Curve'!$C$16 | G19: =IF(F19=0,"—",CEILING(D19/F19,1)) | H19: =D19/$D$19 | K19: Tutorial — tune HP down if needed.
A20: 1 | B20: =CEILING(A20/$B$15,1) | C20: Elite | D20: =$B$6*(1+$B$7)^(A20-1)*$B$8 | E20: =$B$10*(1+$B$11)^(A20-1)*$B$12 | F20: ='Player Stats Curve'!$C$16 | G20: =IF(F20=0,"—",CEILING(D20/F20,1)) | H20: =D20/$D$19
A21: 2 | B21: =CEILING(A21/$B$15,1) | C21: Common | D21: =$B$6*(1+$B$7)^(A21-1) | E21: =$B$10*(1+$B$11)^(A21-1) | F21: ='Player Stats Curve'!$C$17 | G21: =IF(F21=0,"—",CEILING(D21/F21,1)) | H21: =D21/$D$19
A22: 2 | B22: =CEILING(A22/$B$15,1) | C22: Elite | D22: =$B$6*(1+$B$7)^(A22-1)*$B$8 | E22: =$B$10*(1+$B$11)^(A22-1)*$B$12 | F22: ='Player Stats Curve'!$C$17 | G22: =IF(F22=0,"—",CEILING(D22/F22,1)) | H22: =D22/$D$19
A23: 3 | B23: =CEILING(A23/$B$15,1) | C23: Common | D23: =$B$6*(1+$B$7)^(A23-1) | E23: =$B$10*(1+$B$11)^(A23-1) | F23: ='Player Stats Curve'!$C$18 | G23: =IF(F23=0,"—",CEILING(D23/F23,1)) | H23: =D23/$D$19
A24: 3 | B24: =CEILING(A24/$B$15,1) | C24: Elite | D24: =$B$6*(1+$B$7)^(A24-1)*$B$8 | E24: =$B$10*(1+$B$11)^(A24-1)*$B$12 | F24: ='Player Stats Curve'!$C$18 | G24: =IF(F24=0,"—",CEILING(D24/F24,1)) | H24: =D24/$D$19
A25: 4 | B25: =CEILING(A25/$B$15,1) | C25: Common | D25: =$B$6*(1+$B$7)^(A25-1) | E25: =$B$10*(1+$B$11)^(A25-1) | F25: ='Player Stats Curve'!$C$19 | G25: =IF(F25=0,"—",CEILING(D25/F25,1)) | H25: =D25/$D$19
A26: 4 | B26: =CEILING(A26/$B$15,1) | C26: Elite | D26: =$B$6*(1+$B$7)^(A26-1)*$B$8 | E26: =$B$10*(1+$B$11)^(A26-1)*$B$12 | F26: ='Player Stats Curve'!$C$19 | G26: =IF(F26=0,"—",CEILING(D26/F26,1)) | H26: =D26/$D$19
A27: 5 | B27: =CEILING(A27/$B$15,1) | C27: Common | D27: =$B$6*(1+$B$7)^(A27-1) | E27: =$B$10*(1+$B$11)^(A27-1) | F27: ='Player Stats Curve'!$C$20 | G27: =IF(F27=0,"—",CEILING(D27/F27,1)) | H27: =D27/$D$19
A28: 5 | B28: =CEILING(A28/$B$15,1) | C28: Boss | D28: =$B$6*(1+$B$7)^(A28-1)*$B$9 | E28: =$B$10*(1+$B$11)^(A28-1)*$B$13 | F28: ='Player Stats Curve'!$C$20 | G28: =IF(F28=0,"—",CEILING(D28/F28,1)) | H28: =D28/$D$19 | I28: Yes | K28: Zone 1 boss
A29: 6 | B29: =CEILING(A29/$B$15,1) | C29: Common | D29: =$B$6*(1+$B$7)^(A29-1) | E29: =$B$10*(1+$B$11)^(A29-1) | F29: ='Player Stats Curve'!$C$21 | G29: =IF(F29=0,"—",CEILING(D29/F29,1)) | H29: =D29/$D$19
A30: 6 | B30: =CEILING(A30/$B$15,1) | C30: Elite | D30: =$B$6*(1+$B$7)^(A30-1)*$B$8 | E30: =$B$10*(1+$B$11)^(A30-1)*$B$12 | F30: ='Player Stats Curve'!$C$21 | G30: =IF(F30=0,"—",CEILING(D30/F30,1)) | H30: =D30/$D$19
A31: 7 | B31: =CEILING(A31/$B$15,1) | C31: Common | D31: =$B$6*(1+$B$7)^(A31-1) | E31: =$B$10*(1+$B$11)^(A31-1) | F31: ='Player Stats Curve'!$C$22 | G31: =IF(F31=0,"—",CEILING(D31/F31,1)) | H31: =D31/$D$19
A32: 7 | B32: =CEILING(A32/$B$15,1) | C32: Elite | D32: =$B$6*(1+$B$7)^(A32-1)*$B$8 | E32: =$B$10*(1+$B$11)^(A32-1)*$B$12 | F32: ='Player Stats Curve'!$C$22 | G32: =IF(F32=0,"—",CEILING(D32/F32,1)) | H32: =D32/$D$19
A33: 8 | B33: =CEILING(A33/$B$15,1) | C33: Common | D33: =$B$6*(1+$B$7)^(A33-1) | E33: =$B$10*(1+$B$11)^(A33-1) | F33: ='Player Stats Curve'!$C$23 | G33: =IF(F33=0,"—",CEILING(D33/F33,1)) | H33: =D33/$D$19
A34: 8 | B34: =CEILING(A34/$B$15,1) | C34: Elite | D34: =$B$6*(1+$B$7)^(A34-1)*$B$8 | E34: =$B$10*(1+$B$11)^(A34-1)*$B$12 | F34: ='Player Stats Curve'!$C$23 | G34: =IF(F34=0,"—",CEILING(D34/F34,1)) | H34: =D34/$D$19
A35: 9 | B35: =CEILING(A35/$B$15,1) | C35: Common | D35: =$B$6*(1+$B$7)^(A35-1) | E35: =$B$10*(1+$B$11)^(A35-1) | F35: ='Player Stats Curve'!$C$24 | G35: =IF(F35=0,"—",CEILING(D35/F35,1)) | H35: =D35/$D$19
A36: 9 | B36: =CEILING(A36/$B$15,1) | C36: Elite | D36: =$B$6*(1+$B$7)^(A36-1)*$B$8 | E36: =$B$10*(1+$B$11)^(A36-1)*$B$12 | F36: ='Player Stats Curve'!$C$24 | G36: =IF(F36=0,"—",CEILING(D36/F36,1)) | H36: =D36/$D$19
A37: 10 | B37: =CEILING(A37/$B$15,1) | C37: Common | D37: =$B$6*(1+$B$7)^(A37-1) | E37: =$B$10*(1+$B$11)^(A37-1) | F37: ='Player Stats Curve'!$C$25 | G37: =IF(F37=0,"—",CEILING(D37/F37,1)) | H37: =D37/$D$19
A38: 10 | B38: =CEILING(A38/$B$15,1) | C38: Boss | D38: =$B$6*(1+$B$7)^(A38-1)*$B$9 | E38: =$B$10*(1+$B$11)^(A38-1)*$B$13 | F38: ='Player Stats Curve'!$C$25 | G38: =IF(F38=0,"—",CEILING(D38/F38,1)) | H38: =D38/$D$19 | I38: Yes | K38: Zone 2 boss
A39: 11 | B39: =CEILING(A39/$B$15,1) | C39: Common | D39: =$B$6*(1+$B$7)^(A39-1) | E39: =$B$10*(1+$B$11)^(A39-1) | F39: ='Player Stats Curve'!$C$26 | G39: =IF(F39=0,"—",CEILING(D39/F39,1)) | H39: =D39/$D$19
A40: 11 | B40: =CEILING(A40/$B$15,1) | C40: Elite | D40: =$B$6*(1+$B$7)^(A40-1)*$B$8 | E40: =$B$10*(1+$B$11)^(A40-1)*$B$12 | F40: ='Player Stats Curve'!$C$26 | G40: =IF(F40=0,"—",CEILING(D40/F40,1)) | H40: =D40/$D$19
A41: 12 | B41: =CEILING(A41/$B$15,1) | C41: Common | D41: =$B$6*(1+$B$7)^(A41-1) | E41: =$B$10*(1+$B$11)^(A41-1) | F41: ='Player Stats Curve'!$C$27 | G41: =IF(F41=0,"—",CEILING(D41/F41,1)) | H41: =D41/$D$19
A42: 12 | B42: =CEILING(A42/$B$15,1) | C42: Elite | D42: =$B$6*(1+$B$7)^(A42-1)*$B$8 | E42: =$B$10*(1+$B$11)^(A42-1)*$B$12 | F42: ='Player Stats Curve'!$C$27 | G42: =IF(F42=0,"—",CEILING(D42/F42,1)) | H42: =D42/$D$19
...

Sheet Currencies
A1: CURRENCIES
A2: VEIN Crystal earned per floor (from drops + clear bonus) and Shard Crystal accrued per run. Drives the IAP expected-value math in batch 3.
A4: DRIVER INPUTS (mirrored from Assumptions — green text)
A5: Driver | B5: Value
A6: vein_common_amount | B6: =Assumptions!$C$44
A7: vein_elite_amount | B7: =Assumptions!$C$45
A8: vein_boss_amount | B8: =Assumptions!$C$46
A9: sig_common_amount | B9: =Assumptions!$C$47
A10: sig_elite_amount | B10: =Assumptions!$C$48
A11: sig_boss_amount | B11: =Assumptions!$C$49
A12: vein_per_floor_clear_bonus | B12: =Assumptions!$C$58
A13: shard_per_vein_conversion | B13: =Assumptions!$C$57
A14: boss_every_n_floors | B14: =Assumptions!$C$53
A15: max_floor | B15: =Assumptions!$C$6
A17: PER-FLOOR INCOME
A18: Floor | B18: Boss? | C18: Commons | D18: Elites | E18: VEIN earned | F18: SIG earned | G18: Cum. VEIN | H18: Cum. SIG | I18: Cum. Shards | J18: Notes
A19: 1 | C19: ='Drop Rates'!$C$19 | D19: ='Drop Rates'!$D$19 | E19: =C19*$B$6+D19*$B$7+IF(MOD(A19,$B$14)=0,1,0)*$B$8+$B$12 | F19: =C19*Assumptions!$C$35*$B$9+D19*Assumptions!$C$37*$B$10+IF(MOD(A19,$B$14)=0,1,0)*$B$11 | G19: =E19 | H19: =F19 | I19: =G19*$B$13
A20: 2 | C20: ='Drop Rates'!$C$20 | D20: ='Drop Rates'!$D$20 | E20: =C20*$B$6+D20*$B$7+IF(MOD(A20,$B$14)=0,1,0)*$B$8+$B$12 | F20: =C20*Assumptions!$C$35*$B$9+D20*Assumptions!$C$37*$B$10+IF(MOD(A20,$B$14)=0,1,0)*$B$11 | G20: =G19+E20 | H20: =H19+F20 | I20: =G20*$B$13
A21: 3 | C21: ='Drop Rates'!$C$21 | D21: ='Drop Rates'!$D$21 | E21: =C21*$B$6+D21*$B$7+IF(MOD(A21,$B$14)=0,1,0)*$B$8+$B$12 | F21: =C21*Assumptions!$C$35*$B$9+D21*Assumptions!$C$37*$B$10+IF(MOD(A21,$B$14)=0,1,0)*$B$11 | G21: =G20+E21 | H21: =H20+F21 | I21: =G21*$B$13
A22: 4 | C22: ='Drop Rates'!$C$22 | D22: ='Drop Rates'!$D$22 | E22: =C22*$B$6+D22*$B$7+IF(MOD(A22,$B$14)=0,1,0)*$B$8+$B$12 | F22: =C22*Assumptions!$C$35*$B$9+D22*Assumptions!$C$37*$B$10+IF(MOD(A22,$B$14)=0,1,0)*$B$11 | G22: =G21+E22 | H22: =H21+F22 | I22: =G22*$B$13
A23: 5 | B23: Yes | C23: ='Drop Rates'!$C$23 | D23: ='Drop Rates'!$D$23 | E23: =C23*$B$6+D23*$B$7+IF(MOD(A23,$B$14)=0,1,0)*$B$8+$B$12 | F23: =C23*Assumptions!$C$35*$B$9+D23*Assumptions!$C$37*$B$10+IF(MOD(A23,$B$14)=0,1,0)*$B$11 | G23: =G22+E23 | H23: =H22+F23 | I23: =G23*$B$13 | J23: Zone 1 boss — big VEIN/SIG payout
A24: 6 | C24: ='Drop Rates'!$C$24 | D24: ='Drop Rates'!$D$24 | E24: =C24*$B$6+D24*$B$7+IF(MOD(A24,$B$14)=0,1,0)*$B$8+$B$12 | F24: =C24*Assumptions!$C$35*$B$9+D24*Assumptions!$C$37*$B$10+IF(MOD(A24,$B$14)=0,1,0)*$B$11 | G24: =G23+E24 | H24: =H23+F24 | I24: =G24*$B$13
A25: 7 | C25: ='Drop Rates'!$C$25 | D25: ='Drop Rates'!$D$25 | E25: =C25*$B$6+D25*$B$7+IF(MOD(A25,$B$14)=0,1,0)*$B$8+$B$12 | F25: =C25*Assumptions!$C$35*$B$9+D25*Assumptions!$C$37*$B$10+IF(MOD(A25,$B$14)=0,1,0)*$B$11 | G25: =G24+E25 | H25: =H24+F25 | I25: =G25*$B$13
A26: 8 | C26: ='Drop Rates'!$C$26 | D26: ='Drop Rates'!$D$26 | E26: =C26*$B$6+D26*$B$7+IF(MOD(A26,$B$14)=0,1,0)*$B$8+$B$12 | F26: =C26*Assumptions!$C$35*$B$9+D26*Assumptions!$C$37*$B$10+IF(MOD(A26,$B$14)=0,1,0)*$B$11 | G26: =G25+E26 | H26: =H25+F26 | I26: =G26*$B$13
A27: 9 | C27: ='Drop Rates'!$C$27 | D27: ='Drop Rates'!$D$27 | E27: =C27*$B$6+D27*$B$7+IF(MOD(A27,$B$14)=0,1,0)*$B$8+$B$12 | F27: =C27*Assumptions!$C$35*$B$9+D27*Assumptions!$C$37*$B$10+IF(MOD(A27,$B$14)=0,1,0)*$B$11 | G27: =G26+E27 | H27: =H26+F27 | I27: =G27*$B$13
A28: 10 | B28: Yes | C28: ='Drop Rates'!$C$28 | D28: ='Drop Rates'!$D$28 | E28: =C28*$B$6+D28*$B$7+IF(MOD(A28,$B$14)=0,1,0)*$B$8+$B$12 | F28: =C28*Assumptions!$C$35*$B$9+D28*Assumptions!$C$37*$B$10+IF(MOD(A28,$B$14)=0,1,0)*$B$11 | G28: =G27+E28 | H28: =H27+F28 | I28: =G28*$B$13 | J28: Zone 2 boss — big VEIN/SIG payout
A29: 11 | C29: ='Drop Rates'!$C$29 | D29: ='Drop Rates'!$D$29 | E29: =C29*$B$6+D29*$B$7+IF(MOD(A29,$B$14)=0,1,0)*$B$8+$B$12 | F29: =C29*Assumptions!$C$35*$B$9+D29*Assumptions!$C$37*$B$10+IF(MOD(A29,$B$14)=0,1,0)*$B$11 | G29: =G28+E29 | H29: =H28+F29 | I29: =G29*$B$13
A30: 12 | C30: ='Drop Rates'!$C$30 | D30: ='Drop Rates'!$D$30 | E30: =C30*$B$6+D30*$B$7+IF(MOD(A30,$B$14)=0,1,0)*$B$8+$B$12 | F30: =C30*Assumptions!$C$35*$B$9+D30*Assumptions!$C$37*$B$10+IF(MOD(A30,$B$14)=0,1,0)*$B$11 | G30: =G29+E30 | H30: =H29+F30 | I30: =G30*$B$13
A31: 13 | C31: ='Drop Rates'!$C$31 | D31: ='Drop Rates'!$D$31 | E31: =C31*$B$6+D31*$B$7+IF(MOD(A31,$B$14)=0,1,0)*$B$8+$B$12 | F31: =C31*Assumptions!$C$35*$B$9+D31*Assumptions!$C$37*$B$10+IF(MOD(A31,$B$14)=0,1,0)*$B$11 | G31: =G30+E31 | H31: =H30+F31 | I31: =G31*$B$13
A32: 14 | C32: ='Drop Rates'!$C$32 | D32: ='Drop Rates'!$D$32 | E32: =C32*$B$6+D32*$B$7+IF(MOD(A32,$B$14)=0,1,0)*$B$8+$B$12 | F32: =C32*Assumptions!$C$35*$B$9+D32*Assumptions!$C$37*$B$10+IF(MOD(A32,$B$14)=0,1,0)*$B$11 | G32: =G31+E32 | H32: =H31+F32 | I32: =G32*$B$13
A33: 15 | B33: Yes | C33: ='Drop Rates'!$C$33 | D33: ='Drop Rates'!$D$33 | E33: =C33*$B$6+D33*$B$7+IF(MOD(A33,$B$14)=0,1,0)*$B$8+$B$12 | F33: =C33*Assumptions!$C$35*$B$9+D33*Assumptions!$C$37*$B$10+IF(MOD(A33,$B$14)=0,1,0)*$B$11 | G33: =G32+E33 | H33: =H32+F33 | I33: =G33*$B$13 | J33: Zone 3 boss — big VEIN/SIG payout
A34: 16 | C34: ='Drop Rates'!$C$34 | D34: ='Drop Rates'!$D$34 | E34: =C34*$B$6+D34*$B$7+IF(MOD(A34,$B$14)=0,1,0)*$B$8+$B$12 | F34: =C34*Assumptions!$C$35*$B$9+D34*Assumptions!$C$37*$B$10+IF(MOD(A34,$B$14)=0,1,0)*$B$11 | G34: =G33+E34 | H34: =H33+F34 | I34: =G34*$B$13
A35: 17 | C35: ='Drop Rates'!$C$35 | D35: ='Drop Rates'!$D$35 | E35: =C35*$B$6+D35*$B$7+IF(MOD(A35,$B$14)=0,1,0)*$B$8+$B$12 | F35: =C35*Assumptions!$C$35*$B$9+D35*Assumptions!$C$37*$B$10+IF(MOD(A35,$B$14)=0,1,0)*$B$11 | G35: =G34+E35 | H35: =H34+F35 | I35: =G35*$B$13
A36: 18 | C36: ='Drop Rates'!$C$36 | D36: ='Drop Rates'!$D$36 | E36: =C36*$B$6+D36*$B$7+IF(MOD(A36,$B$14)=0,1,0)*$B$8+$B$12 | F36: =C36*Assumptions!$C$35*$B$9+D36*Assumptions!$C$37*$B$10+IF(MOD(A36,$B$14)=0,1,0)*$B$11 | G36: =G35+E36 | H36: =H35+F36 | I36: =G36*$B$13
A37: 19 | C37: ='Drop Rates'!$C$37 | D37: ='Drop Rates'!$D$37 | E37: =C37*$B$6+D37*$B$7+IF(MOD(A37,$B$14)=0,1,0)*$B$8+$B$12 | F37: =C37*Assumptions!$C$35*$B$9+D37*Assumptions!$C$37*$B$10+IF(MOD(A37,$B$14)=0,1,0)*$B$11 | G37: =G36+E37 | H37: =H36+F37 | I37: =G37*$B$13
A38: 20 | B38: Yes | C38: ='Drop Rates'!$C$38 | D38: ='Drop Rates'!$D$38 | E38: =C38*$B$6+D38*$B$7+IF(MOD(A38,$B$14)=0,1,0)*$B$8+$B$12 | F38: =C38*Assumptions!$C$35*$B$9+D38*Assumptions!$C$37*$B$10+IF(MOD(A38,$B$14)=0,1,0)*$B$11 | G38: =G37+E38 | H38: =H37+F38 | I38: =G38*$B$13 | J38: Zone 4 boss — big VEIN/SIG payout
A49: FULL-RUN TOTALS
A50: Total VEIN per full clear (F1→F20) | E50: =SUM(E19:E38)
A51: Total SIG per full clear (F1→F20) | F51: =SUM(F19:F38)
A52: Total Shards per full clear (F1→F20) | I52: =G38*$B$13

Sheet Run Pacing
A1: RUN PACING
A2: Expected combat and clear time per floor. Sum-to-20 is the full-clear run time — a retention proxy used by the IAP and DAU sheets.
A4: DRIVER INPUTS
A5: Driver | B5: Value | D5: Driver | E5: Value
A6: avg_floor_time_min | B6: =Assumptions!$C$54 | D6: combat_seconds_per_turn | E6: =Assumptions!$C$61
A7: boss_every_n_floors | B7: =Assumptions!$C$53 | D7: nav_seconds_per_floor | E7: =Assumptions!$C$62
A8: max_floor | B8: =Assumptions!$C$6 | D8: reward_ui_seconds_per_floor | E8: =Assumptions!$C$63
A10: Methodology: Estimated combat seconds per floor = (commons × common turns-to-kill + elites × elite turns-to-kill + boss × boss turns-to-kill) × 6 seconds per turn. Adds 30s navigation + 15s reward UI per floor.
A12: PER-FLOOR PACING
A13: Floor | B13: Boss? | C13: Commons | D13: Elites | E13: Common TtK | F13: Elite/Boss TtK | G13: Combat sec | H13: Floor total sec | I13: Floor total min | J13: Cum. minutes | K13: Notes
A14: 1 | C14: ='Drop Rates'!$C$19 | D14: ='Drop Rates'!$D$19 | E14: ='Enemy Stats'!$G$19 | F14: ='Enemy Stats'!$G$20 | G14: =(C14*E14 + D14*F14 + IF(MOD(A14,$B$7)=0,1,0)*F14) * $E$6 | H14: =G14+$E$7+$E$8 | I14: =H14/60 | J14: =I14
A15: 2 | C15: ='Drop Rates'!$C$20 | D15: ='Drop Rates'!$D$20 | E15: ='Enemy Stats'!$G$21 | F15: ='Enemy Stats'!$G$22 | G15: =(C15*E15 + D15*F15 + IF(MOD(A15,$B$7)=0,1,0)*F15) * $E$6 | H15: =G15+$E$7+$E$8 | I15: =H15/60 | J15: =J14+I15
A16: 3 | C16: ='Drop Rates'!$C$21 | D16: ='Drop Rates'!$D$21 | E16: ='Enemy Stats'!$G$23 | F16: ='Enemy Stats'!$G$24 | G16: =(C16*E16 + D16*F16 + IF(MOD(A16,$B$7)=0,1,0)*F16) * $E$6 | H16: =G16+$E$7+$E$8 | I16: =H16/60 | J16: =J15+I16
A17: 4 | C17: ='Drop Rates'!$C$22 | D17: ='Drop Rates'!$D$22 | E17: ='Enemy Stats'!$G$25 | F17: ='Enemy Stats'!$G$26 | G17: =(C17*E17 + D17*F17 + IF(MOD(A17,$B$7)=0,1,0)*F17) * $E$6 | H17: =G17+$E$7+$E$8 | I17: =H17/60 | J17: =J16+I17
A18: 5 | B18: Yes | C18: ='Drop Rates'!$C$23 | D18: ='Drop Rates'!$D$23 | E18: ='Enemy Stats'!$G$27 | F18: ='Enemy Stats'!$G$28 | G18: =(C18*E18 + D18*F18 + IF(MOD(A18,$B$7)=0,1,0)*F18) * $E$6 | H18: =G18+$E$7+$E$8 | I18: =H18/60 | J18: =J17+I18 | K18: Zone 1 boss — longer fight
A19: 6 | C19: ='Drop Rates'!$C$24 | D19: ='Drop Rates'!$D$24 | E19: ='Enemy Stats'!$G$29 | F19: ='Enemy Stats'!$G$30 | G19: =(C19*E19 + D19*F19 + IF(MOD(A19,$B$7)=0,1,0)*F19) * $E$6 | H19: =G19+$E$7+$E$8 | I19: =H19/60 | J19: =J18+I19
A20: 7 | C20: ='Drop Rates'!$C$25 | D20: ='Drop Rates'!$D$25 | E20: ='Enemy Stats'!$G$31 | F20: ='Enemy Stats'!$G$32 | G20: =(C20*E20 + D20*F20 + IF(MOD(A20,$B$7)=0,1,0)*F20) * $E$6 | H20: =G20+$E$7+$E$8 | I20: =H20/60 | J20: =J19+I20
A21: 8 | C21: ='Drop Rates'!$C$26 | D21: ='Drop Rates'!$D$26 | E21: ='Enemy Stats'!$G$33 | F21: ='Enemy Stats'!$G$34 | G21: =(C21*E21 + D21*F21 + IF(MOD(A21,$B$7)=0,1,0)*F21) * $E$6 | H21: =G21+$E$7+$E$8 | I21: =H21/60 | J21: =J20+I21
A22: 9 | C22: ='Drop Rates'!$C$27 | D22: ='Drop Rates'!$D$27 | E22: ='Enemy Stats'!$G$35 | F22: ='Enemy Stats'!$G$36 | G22: =(C22*E22 + D22*F22 + IF(MOD(A22,$B$7)=0,1,0)*F22) * $E$6 | H22: =G22+$E$7+$E$8 | I22: =H22/60 | J22: =J21+I22
A23: 10 | B23: Yes | C23: ='Drop Rates'!$C$28 | D23: ='Drop Rates'!$D$28 | E23: ='Enemy Stats'!$G$37 | F23: ='Enemy Stats'!$G$38 | G23: =(C23*E23 + D23*F23 + IF(MOD(A23,$B$7)=0,1,0)*F23) * $E$6 | H23: =G23+$E$7+$E$8 | I23: =H23/60 | J23: =J22+I23 | K23: Zone 2 boss — longer fight
A24: 11 | C24: ='Drop Rates'!$C$29 | D24: ='Drop Rates'!$D$29 | E24: ='Enemy Stats'!$G$39 | F24: ='Enemy Stats'!$G$40 | G24: =(C24*E24 + D24*F24 + IF(MOD(A24,$B$7)=0,1,0)*F24) * $E$6 | H24: =G24+$E$7+$E$8 | I24: =H24/60 | J24: =J23+I24
A25: 12 | C25: ='Drop Rates'!$C$30 | D25: ='Drop Rates'!$D$30 | E25: ='Enemy Stats'!$G$41 | F25: ='Enemy Stats'!$G$42 | G25: =(C25*E25 + D25*F25 + IF(MOD(A25,$B$7)=0,1,0)*F25) * $E$6 | H25: =G25+$E$7+$E$8 | I25: =H25/60 | J25: =J24+I25
A26: 13 | C26: ='Drop Rates'!$C$31 | D26: ='Drop Rates'!$D$31 | E26: ='Enemy Stats'!$G$43 | F26: ='Enemy Stats'!$G$44 | G26: =(C26*E26 + D26*F26 + IF(MOD(A26,$B$7)=0,1,0)*F26) * $E$6 | H26: =G26+$E$7+$E$8 | I26: =H26/60 | J26: =J25+I26
A27: 14 | C27: ='Drop Rates'!$C$32 | D27: ='Drop Rates'!$D$32 | E27: ='Enemy Stats'!$G$45 | F27: ='Enemy Stats'!$G$46 | G27: =(C27*E27 + D27*F27 + IF(MOD(A27,$B$7)=0,1,0)*F27) * $E$6 | H27: =G27+$E$7+$E$8 | I27: =H27/60 | J27: =J26+I27
A28: 15 | B28: Yes | C28: ='Drop Rates'!$C$33 | D28: ='Drop Rates'!$D$33 | E28: ='Enemy Stats'!$G$47 | F28: ='Enemy Stats'!$G$48 | G28: =(C28*E28 + D28*F28 + IF(MOD(A28,$B$7)=0,1,0)*F28) * $E$6 | H28: =G28+$E$7+$E$8 | I28: =H28/60 | J28: =J27+I28 | K28: Zone 3 boss — longer fight
A29: 16 | C29: ='Drop Rates'!$C$34 | D29: ='Drop Rates'!$D$34 | E29: ='Enemy Stats'!$G$49 | F29: ='Enemy Stats'!$G$50 | G29: =(C29*E29 + D29*F29 + IF(MOD(A29,$B$7)=0,1,0)*F29) * $E$6 | H29: =G29+$E$7+$E$8 | I29: =H29/60 | J29: =J28+I29
A30: 17 | C30: ='Drop Rates'!$C$35 | D30: ='Drop Rates'!$D$35 | E30: ='Enemy Stats'!$G$51 | F30: ='Enemy Stats'!$G$52 | G30: =(C30*E30 + D30*F30 + IF(MOD(A30,$B$7)=0,1,0)*F30) * $E$6 | H30: =G30+$E$7+$E$8 | I30: =H30/60 | J30: =J29+I30
A31: 18 | C31: ='Drop Rates'!$C$36 | D31: ='Drop Rates'!$D$36 | E31: ='Enemy Stats'!$G$53 | F31: ='Enemy Stats'!$G$54 | G31: =(C31*E31 + D31*F31 + IF(MOD(A31,$B$7)=0,1,0)*F31) * $E$6 | H31: =G31+$E$7+$E$8 | I31: =H31/60 | J31: =J30+I31
A32: 19 | C32: ='Drop Rates'!$C$37 | D32: ='Drop Rates'!$D$37 | E32: ='Enemy Stats'!$G$55 | F32: ='Enemy Stats'!$G$56 | G32: =(C32*E32 + D32*F32 + IF(MOD(A32,$B$7)=0,1,0)*F32) * $E$6 | H32: =G32+$E$7+$E$8 | I32: =H32/60 | J32: =J31+I32
A33: 20 | B33: Yes | C33: ='Drop Rates'!$C$38 | D33: ='Drop Rates'!$D$38 | E33: ='Enemy Stats'!$G$57 | F33: ='Enemy Stats'!$G$58 | G33: =(C33*E33 + D33*F33 + IF(MOD(A33,$B$7)=0,1,0)*F33) * $E$6 | H33: =G33+$E$7+$E$8 | I33: =H33/60 | J33: =J32+I33 | K33: Zone 4 boss — longer fight
A44: RUN PACING SUMMARY
A45: Total full-clear time (minutes) | I45: =SUM(I14:I33)
A46: Total full-clear time (hours) | I46: =SUM(I14:I33)/60
A47: Average minutes per floor (target = avg_floor_time_min) | I47: =AVERAGE(I14:I33)
A48: Delta vs target (negative = faster than target) | I48: =AVERAGE(I14:I33) - $B$6

Sheet Mutation Costs
A1: MUTATION COSTS
A2: SIG upgrade costs by rarity × level. Balance check at bottom: how many full runs to outfit one of each rarity.
A4: DRIVER INPUTS (mirrored from Assumptions — green text)
A5: Driver | B5: Value
A6: sig_cost_base | B6: =Assumptions!$C$66
A7: sig_cost_level_growth | B7: =Assumptions!$C$67
A8: common_mult | B8: =Assumptions!$C$68
A9: uncommon_mult | B9: =Assumptions!$C$69
A10: rare_mult | B10: =Assumptions!$C$70
A11: epic_mult | B11: =Assumptions!$C$71
A12: mutations_slot_cap | B12: =Assumptions!$C$72
A13: total_sig_per_run | B13: =Currencies!$F$51
A15: SIG COST MATRIX (per upgrade)
A16: Rarity | B16: Mk I cost | C16: Mk II cost | D16: Mk III cost | E16: Total to Mk III | F16: Runs needed* | G16: vs Common | H16: Notes
A17: Common | B17: =ROUND($B$6*$B$8,0) | C17: =ROUND($B$6*$B$8*$B$7,0) | D17: =ROUND($B$6*$B$8*$B$7^2,0) | E17: =B17+C17+D17 | F17: =CEILING(E17/$B$13,1) | G17: =E17/$E$17 | H17: Reference tier.
A18: Uncommon | B18: =ROUND($B$6*$B$9,0) | C18: =ROUND($B$6*$B$9*$B$7,0) | D18: =ROUND($B$6*$B$9*$B$7^2,0) | E18: =B18+C18+D18 | F18: =CEILING(E18/$B$13,1) | G18: =E18/$E$17 | H18: Crafted from 3 Commons + 5 Mod tokens.
A19: Rare | B19: =ROUND($B$6*$B$10,0) | C19: =ROUND($B$6*$B$10*$B$7,0) | D19: =ROUND($B$6*$B$10*$B$7^2,0) | E19: =B19+C19+D19 | F19: =CEILING(E19/$B$13,1) | G19: =E19/$E$17 | H19: Drops from elites (10%) and bosses (60%).
A20: Epic | B20: =ROUND($B$6*$B$11,0) | C20: =ROUND($B$6*$B$11*$B$7,0) | D20: =ROUND($B$6*$B$11*$B$7^2,0) | E20: =B20+C20+D20 | F20: =CEILING(E20/$B$13,1) | G20: =E20/$E$17 | H20: Drops from bosses only (15%). Late-game gear.
A21: BALANCE CHECK
A22: Total SIG for full kit (one of each rarity to Mk III) | E22: =SUM(E17:E20)
A23: Runs needed for full kit | F23: =CEILING(E22/$B$13,1)
A24: Total SIG earned per run (reference) | E24: =$B$13
A26: *Runs-needed assumes the player banks ALL SIG into a single mutation, which is unrealistic. Real grind will be 2-3x higher when SIG is split across multiple mutations being leveled in parallel. Use this column as a floor, not an expectation.

Sheet IAP Catalog
A1: IAP CATALOG
A2: Six SKUs with USD price, currency grant, and expected-value analysis. Time-saved column converts purchases to minutes of grinding eliminated.
A4: DRIVER INPUTS (mirrored — green text)
A5: Driver | B5: Value
A6: total_vein_per_run | B6: =Currencies!$E$50
A7: total_shards_per_run | B7: =Currencies!$I$52
A8: total_run_min | B8: ='Run Pacing'!$I$45
A9: target_arppu_usd | B9: =Assumptions!$C$88
A10: target_conversion | B10: =Assumptions!$C$89
A11: VEIN earned per minute (derived) | B11: =$B$6/$B$8
A12: Shards earned per minute (derived) | B12: =$B$7/$B$8
A14: PRODUCT CATALOG
A15: SKU | B15: Type | C15: USD | D15: VEIN | E15: Shards | F15: $ per VEIN | G15: $ per Shard | H15: Minutes saved | I15: Value rating | J15: Notes
A16: VEIN Pack — Small | B16: VEIN | C16: =Assumptions!$C$75 | D16: =Assumptions!$C$76 | E16: — | F16: =C16/D16 | G16: — | H16: =D16/$B$11 | I16: =IF(H16/C16>=30,"Strong",IF(H16/C16>=10,"Fair","Weak")) | J16: Entry-level impulse purchase.
A17: VEIN Pack — Medium | B17: VEIN | C17: =Assumptions!$C$77 | D17: =Assumptions!$C$78 | E17: — | F17: =C17/D17 | G17: — | H17: =D17/$B$11 | I17: =IF(H17/C17>=30,"Strong",IF(H17/C17>=10,"Fair","Weak")) | J17: 20% bulk bonus. The 'recommended' sticker goes here.
A18: VEIN Pack — Large | B18: VEIN | C18: =Assumptions!$C$79 | D18: =Assumptions!$C$80 | E18: — | F18: =C18/D18 | G18: — | H18: =D18/$B$11 | I18: =IF(H18/C18>=30,"Strong",IF(H18/C18>=10,"Fair","Weak")) | J18: Whale tier. 50% bulk bonus.
A19: Shard Pack — Small | B19: Shard | C19: =Assumptions!$C$81 | D19: — | E19: =Assumptions!$C$82 | F19: — | G19: =C19/E19 | H19: =E19/$B$12 | I19: =IF(H19/C19>=30,"Strong",IF(H19/C19>=10,"Fair","Weak")) | J19: Premium-currency entry tier.
A20: Shard Pack — Large | B20: Shard | C20: =Assumptions!$C$83 | D20: — | E20: =Assumptions!$C$84 | F20: — | G20: =C20/E20 | H20: =E20/$B$12 | I20: =IF(H20/C20>=30,"Strong",IF(H20/C20>=10,"Fair","Weak")) | J20: Premium-currency whale tier. 20% bulk bonus.
A21: Deep Signal Pass | B21: Pass | C21: =Assumptions!$C$85 | D21: =Assumptions!$C$86 | E21: =Assumptions!$C$87 | F21: =C21/D21 | G21: =C21/E21 | H21: =D21/$B$11+E21/$B$12 | I21: =IF(H21/C21>=30,"Strong",IF(H21/C21>=10,"Fair","Weak")) | J21: 30-day battle pass. Combined VEIN + Shard grant + cosmetics (not modeled in $ value).
A22: CATALOG SUMMARY
A23: Cheapest entry point (USD) | C23: =MIN(C16:C21)
A24: Highest-tier purchase (USD) | C24: =MAX(C16:C21)
A25: Average price (USD) | C25: =AVERAGE(C16:C21)
A26: Median price (USD) — feeds ARPPU calc in Revenue | C26: =MEDIAN(C16:C21)

Sheet DAU & Revenue Model
A1: DAU & REVENUE MODEL
A2: 12-month projection across three scenarios. DAU grows geometrically from starting value; revenue = DAU × conversion × ARPPU × (1 − platform cut).
A4: DRIVER INPUTS (mirrored from Assumptions — green text)
A5: Driver | B5: Pessimistic | C5: Conservative | D5: Target | N5: Notes
A6: Starting DAU (M1) | B6: =Assumptions!$C$92 | C6: =Assumptions!$C$96 | D6: =Assumptions!$C$100
A7: MoM DAU growth | B7: =Assumptions!$C$93 | C7: =Assumptions!$C$97 | D7: =Assumptions!$C$101
A8: Conversion (free→paying) | B8: =Assumptions!$C$94 | C8: =Assumptions!$C$98 | D8: =Assumptions!$C$102
A9: Monthly ARPPU | B9: =Assumptions!$C$95 | C9: =Assumptions!$C$99 | D9: =Assumptions!$C$103
A10: Platform cut | B10: =Assumptions!$C$104 | C10: =Assumptions!$C$104 | D10: =Assumptions!$C$104
A12: Metric | B12: M1 | C12: M2 | D12: M3 | E12: M4 | F12: M5 | G12: M6 | H12: M7 | I12: M8 | J12: M9 | K12: M10 | L12: M11 | M12: M12 | N12: 12-mo Total
A13: PESSIMISTIC SCENARIO
A14: DAU | B14: =ROUND($B$6*(1+$B$7)^(1-1),0) | C14: =ROUND($B$6*(1+$B$7)^(2-1),0) | D14: =ROUND($B$6*(1+$B$7)^(3-1),0) | E14: =ROUND($B$6*(1+$B$7)^(4-1),0) | F14: =ROUND($B$6*(1+$B$7)^(5-1),0) | G14: =ROUND($B$6*(1+$B$7)^(6-1),0) | H14: =ROUND($B$6*(1+$B$7)^(7-1),0) | I14: =ROUND($B$6*(1+$B$7)^(8-1),0) | J14: =ROUND($B$6*(1+$B$7)^(9-1),0) | K14: =ROUND($B$6*(1+$B$7)^(10-1),0) | L14: =ROUND($B$6*(1+$B$7)^(11-1),0) | M14: =ROUND($B$6*(1+$B$7)^(12-1),0) | N14: =SUM(B14:M14)
A15: Paying users | B15: =ROUND(B14*$B$8,0) | C15: =ROUND(C14*$B$8,0) | D15: =ROUND(D14*$B$8,0) | E15: =ROUND(E14*$B$8,0) | F15: =ROUND(F14*$B$8,0) | G15: =ROUND(G14*$B$8,0) | H15: =ROUND(H14*$B$8,0) | I15: =ROUND(I14*$B$8,0) | ... M15: =ROUND(M14*$B$8,0) | N15: =SUM(B15:M15)
A16: Gross revenue (USD) | B16: =B15*$B$9 | C16: =C15*$B$9 | D16: =D15*$B$9 | E16: =E15*$B$9 | F16: =F15*$B$9 | G16: =G15*$B$9 | H16: =H15*$B$9 | I16: =I15*$B$9 | ... M16: =M15*$B$9 | N16: =SUM(B16:M16)
A17: Platform cut (USD) | B17: =B16*$B$10 | C17: =C16*$B$10 | D17: =D16*$B$10 | E17: =E16*$B$10 | F17: =F16*$B$10 | G17: =G16*$B$10 | H17: =H16*$B$10 | I17: =I16*$B$10 | ... M17: =M16*$B$10 | N17: =SUM(B17:M17)
A18: Net revenue (USD) | B18: =B16-B17 | C18: =C16-C17 | D18: =D16-D17 | E18: =E16-E17 | F18: =F16-F17 | G18: =G16-G17 | H18: =H16-H17 | I18: =I16-I17 | ... M18: =M16-M17 | N18: =SUM(B18:M18)
A19: Cumulative net rev (USD) | B19: =B18 | C19: =B19+C18 | D19: =C19+D18 | E19: =D19+E18 | F19: =E19+F18 | G19: =F19+G18 | H19: =G19+H18 | I19: =H19+I18 | J19: =I19+J18 | ... M19: =L19+M18 | N19: =M19
A21: CONSERVATIVE SCENARIO
A22: DAU | B22: =ROUND($C$6*(1+$C$7)^(1-1),0) | C22: =ROUND($C$6*(1+$C$7)^(2-1),0) | D22: =ROUND($C$6*(1+$C$7)^(3-1),0) | E22: =ROUND($C$6*(1+$C$7)^(4-1),0) | F22: =ROUND($C$6*(1+$C$7)^(5-1),0) | G22: =ROUND($C$6*(1+$C$7)^(6-1),0) | H22: =ROUND($C$6*(1+$C$7)^(7-1),0) | I22: =ROUND($C$6*(1+$C$7)^(8-1),0) | J22: =ROUND($C$6*(1+$C$7)^(9-1),0) | K22: =ROUND($C$6*(1+$C$7)^(10-1),0) | L22: =ROUND($C$6*(1+$C$7)^(11-1),0) | M22: =ROUND($C$6*(1+$C$7)^(12-1),0) | N22: =SUM(B22:M22)
A23: Paying users | B23: =ROUND(B22*$C$8,0) | C23: =ROUND(C22*$C$8,0) | D23: =ROUND(D22*$C$8,0) | E23: =ROUND(E22*$C$8,0) | F23: =ROUND(F22*$C$8,0) | G23: =ROUND(G22*$C$8,0) | H23: =ROUND(H22*$C$8,0) | I23: =ROUND(I22*$C$8,0) | ... M23: =ROUND(M22*$C$8,0) | N23: =SUM(B23:M23)
A24: Gross revenue (USD) | B24: =B23*$C$9 | C24: =C23*$C$9 | D24: =D23*$C$9 | E24: =E23*$C$9 | F24: =F23*$C$9 | G24: =G23*$C$9 | H24: =H23*$C$9 | I24: =I23*$C$9 | ... M24: =M23*$C$9 | N24: =SUM(B24:M24)
A25: Platform cut (USD) | B25: =B24*$C$10 | C25: =C24*$C$10 | D25: =D24*$C$10 | E25: =E24*$C$10 | F25: =F24*$C$10 | G25: =G24*$C$10 | H25: =H24*$C$10 | I25: =I24*$C$10 | ... M25: =M24*$C$10 | N25: =SUM(B25:M25)
A26: Net revenue (USD) | B26: =B24-B25 | C26: =C24-C25 | D26: =D24-D25 | E26: =E24-E25 | F26: =F24-F25 | G26: =G24-G25 | H26: =H24-H25 | I26: =I24-I25 | ... M26: =M24-M25 | N26: =SUM(B26:M26)
A27: Cumulative net rev (USD) | B27: =B26 | C27: =B27+C26 | D27: =C27+D26 | E27: =D27+E26 | F27: =E27+F26 | G27: =F27+G26 | H27: =G27+H26 | I27: =H27+I26 | J27: =I27+J26 | ... M27: =L27+M26 | N27: =M27
A29: TARGET SCENARIO
A30: DAU | B30: =ROUND($D$6*(1+$D$7)^(1-1),0) | C30: =ROUND($D$6*(1+$D$7)^(2-1),0) | D30: =ROUND($D$6*(1+$D$7)^(3-1),0) | E30: =ROUND($D$6*(1+$D$7)^(4-1),0) | F30: =ROUND($D$6*(1+$D$7)^(5-1),0) | G30: =ROUND($D$6*(1+$D$7)^(6-1),0) | H30: =ROUND($D$6*(1+$D$7)^(7-1),0) | I30: =ROUND($D$6*(1+$D$7)^(8-1),0) | J30: =ROUND($D$6*(1+$D$7)^(9-1),0) | K30: =ROUND($D$6*(1+$D$7)^(10-1),0) | L30: =ROUND($D$6*(1+$D$7)^(11-1),0) | M30: =ROUND($D$6*(1+$D$7)^(12-1),0) | N30: =SUM(B30:M30)
A31: Paying users | B31: =ROUND(B30*$D$8,0) | C31: =ROUND(C30*$D$8,0) | D31: =ROUND(D30*$D$8,0) | E31: =ROUND(E30*$D$8,0) | F31: =ROUND(F30*$D$8,0) | G31: =ROUND(G30*$D$8,0) | H31: =ROUND(H30*$D$8,0) | I31: =ROUND(I30*$D$8,0) | ... M31: =ROUND(M30*$D$8,0) | N31: =SUM(B31:M31)
A32: Gross revenue (USD) | B32: =B31*$D$9 | C32: =C31*$D$9 | D32: =D31*$D$9 | E32: =E31*$D$9 | F32: =F31*$D$9 | G32: =G31*$D$9 | H32: =H31*$D$9 | I32: =I31*$D$9 | ... M32: =M31*$D$9 | N32: =SUM(B32:M32)
A33: Platform cut (USD) | B33: =B32*$D$10 | C33: =C32*$D$10 | D33: =D32*$D$10 | E33: =E32*$D$10 | F33: =F32*$D$10 | G33: =G32*$D$10 | H33: =H32*$D$10 | I33: =I32*$D$10 | ... M33: =M32*$D$10 | N33: =SUM(B33:M33)
A34: Net revenue (USD) | B34: =B32-B33 | C34: =C32-C33 | D34: =D32-D33 | E34: =E32-E33 | F34: =F32-F33 | G34: =G32-G33 | H34: =H32-H33 | I34: =I32-I33 | ... M34: =M32-M33 | N34: =SUM(B34:M34)
A35: Cumulative net rev (USD) | B35: =B34 | C35: =B35+C34 | D35: =C35+D34 | E35: =D35+E34 | F35: =E35+F34 | G35: =F35+G34 | H35: =G35+H34 | I35: =H35+I34 | J35: =I35+J34 | ... M35: =L35+M34 | N35: =M35
A37: COMPARISON SUMMARY — 12-MONTH TOTALS
A38: Metric | B38: Pessimistic | C38: Conservative | D38: Target | N38: Δ Target vs Cons
A39: Total Net Revenue (12 mo) | B39: =N18 | C39: =N26 | D39: =N34 | N39: =D39-C39
A40: DAU at M12 | B40: =M14 | C40: =M22 | D40: =M30 | N40: =D40-C40
A41: Paying Users at M12 | B41: =M15 | C41: =M23 | D41: =M31 | N41: =D41-C41

Sheet Cost Projection
A1: COST PROJECTION
A2: Monthly costs and net profit per scenario. Firebase scales with DAU; dev burn is flat; UA spend is per-scenario. Pulls net revenue from DAU & Revenue Model to close the loop.
A4: DRIVER INPUTS (mirrored — green text)
A5: Driver | B5: Pessimistic | C5: Conservative | D5: Target | N5: Notes
A6: Firebase $ per DAU per mo | B6: =Assumptions!$C$107 | C6: =Assumptions!$C$107 | D6: =Assumptions!$C$107
A7: Dev burn monthly USD | B7: =Assumptions!$C$108 | C7: =Assumptions!$C$108 | D7: =Assumptions!$C$108
A8: UA spend monthly USD | B8: =Assumptions!$C$109 | C8: =Assumptions!$C$110 | D8: =Assumptions!$C$111
A10: Metric | B10: M1 | C10: M2 | D10: M3 | E10: M4 | F10: M5 | G10: M6 | H10: M7 | I10: M8 | J10: M9 | K10: M10 | L10: M11 | M10: M12 | N10: 12-mo Total
A11: PESSIMISTIC SCENARIO
A12: Firebase cost (USD) | B12: ='DAU & Revenue Model'!B14*$B$6 | C12: ='DAU & Revenue Model'!C14*$B$6 | D12: ='DAU & Revenue Model'!D14*$B$6 | E12: ='DAU & Revenue Model'!E14*$B$6 | F12: ='DAU & Revenue Model'!F14*$B$6 | G12: ='DAU & Revenue Model'!G14*$B$6 | H12: ='DAU & Revenue Model'!H14*$B$6 | I12: ='DAU & Revenue Model'!I14*$B$6 | ... M12: ='DAU & Revenue Model'!M14*$B$6 | N12: =SUM(B12:M12)
A13: Dev burn (USD) | B13: =$B$7 | C13: =$B$7 | D13: =$B$7 | E13: =$B$7 | F13: =$B$7 | G13: =$B$7 | H13: =$B$7 | I13: =$B$7 | ... M13: =$B$7 | N13: =SUM(B13:M13)
A14: UA spend (USD) | B14: =$B$8 | C14: =$B$8 | D14: =$B$8 | E14: =$B$8 | F14: =$B$8 | G14: =$B$8 | H14: =$B$8 | I14: =$B$8 | ... M14: =$B$8 | N14: =SUM(B14:M14)
A15: Total costs (USD) | B15: =B12+B13+B14 | C15: =C12+C13+C14 | D15: =D12+D13+D14 | E15: =E12+E13+E14 | F15: =F12+F13+F14 | G15: =G12+G13+G14 | H15: =H12+H13+H14 | I15: =I12+I13+I14 | ... M15: =M12+M13+M14 | N15: =SUM(B15:M15)
A16: Net revenue (USD) | B16: ='DAU & Revenue Model'!B18 | C16: ='DAU & Revenue Model'!C18 | D16: ='DAU & Revenue Model'!D18 | E16: ='DAU & Revenue Model'!E18 | F16: ='DAU & Revenue Model'!F18 | G16: ='DAU & Revenue Model'!G18 | H16: ='DAU & Revenue Model'!H18 | I16: ='DAU & Revenue Model'!I18 | ... M16: ='DAU & Revenue Model'!M18 | N16: =SUM(B16:M16)
A17: Net profit (USD) | B17: =B16-B15 | C17: =C16-C15 | D17: =D16-D15 | E17: =E16-E15 | F17: =F16-F15 | G17: =G16-G15 | H17: =H16-H15 | I17: =I16-I15 | ... M17: =M16-M15 | N17: =SUM(B17:M17)
A18: Cumulative profit (USD) | B18: =B17 | C18: =B18+C17 | D18: =C18+D17 | E18: =D18+E17 | F18: =E18+F17 | G18: =F18+G17 | H18: =G18+H17 | I18: =H18+I17 | J18: =I18+J17 | ... M18: =L18+M17 | N18: =M18
A20: CONSERVATIVE SCENARIO
A21: Firebase cost (USD) | B21: ='DAU & Revenue Model'!B22*$C$6 | C21: ='DAU & Revenue Model'!C22*$C$6 | D21: ='DAU & Revenue Model'!D22*$C$6 | E21: ='DAU & Revenue Model'!E22*$C$6 | F21: ='DAU & Revenue Model'!F22*$C$6 | G21: ='DAU & Revenue Model'!G22*$C$6 | H21: ='DAU & Revenue Model'!H22*$C$6 | I21: ='DAU & Revenue Model'!I22*$C$6 | ... M21: ='DAU & Revenue Model'!M22*$C$6 | N21: =SUM(B21:M21)
A22: Dev burn (USD) | B22: =$C$7 | C22: =$C$7 | D22: =$C$7 | E22: =$C$7 | F22: =$C$7 | G22: =$C$7 | H22: =$C$7 | I22: =$C$7 | ... M22: =$C$7 | N22: =SUM(B22:M22)
A23: UA spend (USD) | B23: =$C$8 | C23: =$C$8 | D23: =$C$8 | E23: =$C$8 | F23: =$C$8 | G23: =$C$8 | H23: =$C$8 | I23: =$C$8 | ... M23: =$C$8 | N23: =SUM(B23:M23)
A24: Total costs (USD) | B24: =B21+B22+B23 | C24: =C21+C22+C23 | D24: =D21+D22+D23 | E24: =E21+E22+E23 | F24: =F21+F22+F23 | G24: =G21+G22+G23 | H24: =H21+H22+H23 | I24: =I21+I22+I23 | ... M24: =M21+M22+M23 | N24: =SUM(B24:M24)
A25: Net revenue (USD) | B25: ='DAU & Revenue Model'!B26 | C25: ='DAU & Revenue Model'!C26 | D25: ='DAU & Revenue Model'!D26 | E25: ='DAU & Revenue Model'!E26 | F25: ='DAU & Revenue Model'!F26 | G25: ='DAU & Revenue Model'!G26 | H25: ='DAU & Revenue Model'!H26 | I25: ='DAU & Revenue Model'!I26 | ... M25: ='DAU & Revenue Model'!M26 | N25: =SUM(B25:M25)
A26: Net profit (USD) | B26: =B25-B24 | C26: =C25-C24 | D26: =D25-D24 | E26: =E25-E24 | F26: =F25-F24 | G26: =G25-G24 | H26: =H25-H24 | I26: =I25-I24 | ... M26: =M25-M24 | N26: =SUM(B26:M26)
A27: Cumulative profit (USD) | B27: =B26 | C27: =B27+C26 | D27: =C27+D26 | E27: =D27+E26 | F27: =E27+F26 | G27: =F27+G26 | H27: =G27+H26 | I27: =H27+I26 | J27: =I27+J26 | ... M27: =L27+M26 | N27: =M27
A29: TARGET SCENARIO
A30: Firebase cost (USD) | B30: ='DAU & Revenue Model'!B30*$D$6 | C30: ='DAU & Revenue Model'!C30*$D$6 | D30: ='DAU & Revenue Model'!D30*$D$6 | E30: ='DAU & Revenue Model'!E30*$D$6 | F30: ='DAU & Revenue Model'!F30*$D$6 | G30: ='DAU & Revenue Model'!G30*$D$6 | H30: ='DAU & Revenue Model'!H30*$D$6 | I30: ='DAU & Revenue Model'!I30*$D$6 | ... M30: ='DAU & Revenue Model'!M30*$D$6 | N30: =SUM(B30:M30)
A31: Dev burn (USD) | B31: =$D$7 | C31: =$D$7 | D31: =$D$7 | E31: =$D$7 | F31: =$D$7 | G31: =$D$7 | H31: =$D$7 | I31: =$D$7 | ... M31: =$D$7 | N31: =SUM(B31:M31)
A32: UA spend (USD) | B32: =$D$8 | C32: =$D$8 | D32: =$D$8 | E32: =$D$8 | F32: =$D$8 | G32: =$D$8 | H32: =$D$8 | I32: =$D$8 | ... M32: =$D$8 | N32: =SUM(B32:M32)
A33: Total costs (USD) | B33: =B30+B31+B32 | C33: =C30+C31+C32 | D33: =D30+D31+D32 | E33: =E30+E31+E32 | F33: =F30+F31+F32 | G33: =G30+G31+G32 | H33: =H30+H31+H32 | I33: =I30+I31+I32 | ... M33: =M30+M31+M32 | N33: =SUM(B33:M33)
A34: Net revenue (USD) | B34: ='DAU & Revenue Model'!B34 | C34: ='DAU & Revenue Model'!C34 | D34: ='DAU & Revenue Model'!D34 | E34: ='DAU & Revenue Model'!E34 | F34: ='DAU & Revenue Model'!F34 | G34: ='DAU & Revenue Model'!G34 | H34: ='DAU & Revenue Model'!H34 | I34: ='DAU & Revenue Model'!I34 | ... M34: ='DAU & Revenue Model'!M34 | N34: =SUM(B34:M34)
A35: Net profit (USD) | B35: =B34-B33 | C35: =C34-C33 | D35: =D34-D33 | E35: =E34-E33 | F35: =F34-F33 | G35: =G34-G33 | H35: =H34-H33 | I35: =I34-I33 | ... M35: =M34-M33 | N35: =SUM(B35:M35)
A36: Cumulative profit (USD) | B36: =B35 | C36: =B36+C35 | D36: =C36+D35 | E36: =D36+E35 | F36: =E36+F35 | G36: =F36+G35 | H36: =G36+H35 | I36: =H36+I35 | J36: =I36+J35 | ... M36: =L36+M35 | N36: =M36
A38: BREAKEVEN ANALYSIS
A39: Metric | B39: Pessimistic | C39: Conservative | D39: Target | N39: Notes
A40: 12-month cumulative profit | B40: =N18 | C40: =N27 | D40: =N36 | N40: Negative = year ends in the red
A41: First profitable month (cum > 0) | B41: =IFERROR("M"&MATCH(TRUE(),INDEX(B18:M18>0,0),0),"Not in 12 mo") | C41: =IFERROR("M"&MATCH(TRUE(),INDEX(B27:M27>0,0),0),"Not in 12 mo") | D41: =IFERROR("M"&MATCH(TRUE(),INDEX(B36:M36>0,0),0),"Not in 12 mo") | N41: When the project recoups
A42: 12-mo ROI (cum profit ÷ 12-mo costs) | B42: =N18/N15 | C42: =N27/N24 | D42: =N36/N33 | N42: >0% means net positive

Sheet Pass Sensitivity
A1: PASS SENSITIVITY
